Workbook

Sheet 工作表2
A1: Samsung | B1: TAIYO | C1: Murata | D1: Size L x Wmm (Inch) | E1: Thickness(mm) | F1: Temperature Characteristic | G1: Temp.Characteristic | H1: Capacitance | I1: Tolerance | J1: Rated Volt(Vdc) | K1: Remark | L1: L/T | M1: MOQ
A2: CL03C470JB3NNNC | C2: GRM0335C1H101JA01D | D2: 0.6 x 0.3(0201) | E2: 0.3mm | F2: COG | G2: -55 to 125℃ | H2: 101 | I2: ±5 % | J2: 50V
A3: CL03C330JB3NNNC | C3: GRM0335C1H101JA01D | D3: 0.6 x 0.3(0201) | E3: 0.3mm | F3: COG | G3: -55 to 125℃ | H3: 101 | I3: ±5 % | J3: 50V
C4: GRM033R71E103KE14D | D4: 0.6 x 0.3(0201) | E4: 0.3mm | F4: COG | G4: -55 to 125℃ | H4: 103 | I4: ±10 % | J4: 25V
A5: CL03C101JB3NNNC | C5: GRM033R71E103KE14D | D5: 0.6 x 0.3(0201) | E5: 0.3mm | F5: X7R | G5: -55 to 125℃ | H5: 103 | I5: ±10 % | J5: 50V
A6: CL03A104KP3NNNC | B6: LMK063BJ104KP-F | D6: 0.6 x 0.3(0201) | E6: 0.3mm | F6: X5R | G6: -55 to 85℃ | H6: 104 | I6: ±10 % | J6: 10V
A7: CL03A104KO3NNNC | B7: EMK063BJ104KP-F | D7: 0.6 x 0.3(0201) | E7: 0.3mm | F7: X5R | G7: -55 to 85℃ | H7: 104 | I7: ±10 % | J7: 16V
C8: GRM033C81C104KE14D | D8: 0.6 x 0.3(0201) | E8: 0.3mm | F8: X6S | G8: -55 to 105℃ | H8: 104 | I8: ±10 % | J8: 16V
A9: CL03A104KA3NNNC | B9: TMK063ABJ104KP-F | C9: GRM033R61E104KE14D | D9: 0.6 x 0.3(0201) | E9: 0.3mm | F9: X5R | G9: -55 to 85℃ | H9: 104 | I9: ±10 % | J9: 25V
A10: CL03A104KQ3NNNC | C10: GRM033R60J104KE19D | D10: 0.6 x 0.3(0201) | E10: 0.3mm | F10: X5R | G10: -55 to 85℃ | H10: 104 | I10: ±10 % | J10: 6.3V
A11: CL03A105MP3NSNC | B11: LDK063ABJ105MP-F | C11: GRM033R61A105ME44D | D11: 0.6 x 0.3(0201) | E11: 0.3mm | F11: X5R | G11: -55 to 85℃ | H11: 105 | I11: ±20 % | J11: 10V
C12: GRM033R61A105ME15D | D12: 0.6 x 0.3(0201) | E12: 0.3mm | F12: X5R | G12: -55 to 85℃ | H12: 105 | I12: ±20 % | J12: 10V
C13: GRM033C81A105ME05D | D13: 0.6 x 0.3(0201) | E13: 0.3mm | F13: X6S | G13: -55 to 105℃ | H13: 105 | I13: ±20 % | J13: 10V
A14: CL03A105MO3NRNC | C14: GRM033R61C105ME15D | D14: 0.6 x 0.3(0201) | E14: 0.3mm | F14: X5R | G14: -55 to 85℃ | H14: 105 | I14: ±20 % | J14: 16V
C15: GRM033D70E105ME15D | D15: 0.6 x 0.3(0201) | E15: 0.3mm | F15: X7T | G15: -55 to 125℃ | H15: 105 | I15: ±20 % | J15: 2.5V
C16: GRM033C81E105KE14# | D16: 0.6 x 0.3(0201) | E16: 0.3mm | F16: X6S | G16: =VLOOKUP(F16,材質!A:B,2,0) -> -55 to 105℃ | H16: 105 | I16: ±10 % | J16: 25V
C17: GRM032R60G105ME05D | D17: 0.6 x 0.3(0201) | E17: 0.2mm | F17: X5R | G17: -55 to 85℃ | H17: 105 | I17: ±20 % | J17: 4V
A18: CL03A105MR3CSNC | C18: GRM033R60G105MEA2D | D18: 0.6 x 0.3(0201) | E18: 0.3mm | F18: X5R | G18: -55 to 85℃ | H18: 105 | I18: ±20 % | J18: 4V
C19: GRM033C80G105ME05* | D19: 0.6 x 0.3(0201) | E19: 0.3mm | F19: X6S | G19: -55 to 105℃ | H19: 105 | I19: ±20 % | J19: 4V
C20: GRM032D80G105ME01D | D20: 0.6 x 0.3(0201) | E20: 0.2mm | F20: X6T | G20: -55 to 105℃ | H20: 105 | I20: ±20 % | J20: 4V
C21: GRM033D70G105ME01D | D21: 0.6 x 0.3(0201) | E21: 0.3mm | F21: X7T | G21: -55 to 125℃ | H21: 105 | I21: ±20 % | J21: 4V
A22: CL03A105KQ3CSNC | B22: JMK063ABJ105KP-F | C22: GRM033R60J105KEA2D | D22: 0.6 x 0.3(0201) | E22: 0.3mm | F22: X5R | G22: -55 to 85℃ | H22: 105 | I22: ±10 % | J22: 6.3V
B23: JDK063ABJ105KP-F | D23: 0.6 x 0.3(0201) | E23: 0.3mm | F23: X5R | G23: -55 to 85℃ | H23: 105 | I23: ±10 % | J23: 6.3V
A24: CL03A105MQ3CSNC | B24: JDK063BJ105MP-FD | C24: GRM033R60J105MEA2D | D24: 0.6 x 0.3(0201) | E24: 0.3mm | F24: X5R | G24: -55 to 85℃ | H24: 105 | I24: ±20 % | J24: 6.3V
B25: JMK063ABJ105MP-F | D25: 0.6 x 0.3(0201) | E25: 0.3mm | F25: X5R | G25: -55 to 85℃ | H25: 105 | I25: ±20 % | J25: 6.3V
C26: GRM033C80J105ME05D | D26: 0.6 x 0.3(0201) | E26: 0.3mm | F26: X6S | G26: -55 to 105℃ | H26: 105 | I26: ±20 % | J26: 6.3V
C27: GRM033D70J105ME01D | D27: 0.6 x 0.3(0201) | E27: 0.3mm | F27: X7T | G27: -55 to 125℃ | H27: 105 | I27: ±20 % | J27: 6.3V
C28: GRM0335C1H121JA01D | D28: 0.6 x 0.3(0201) | E28: 0.3mm | F28: COG | G28: -55 to 125℃ | H28: 121 | I28: ±5 % | J28: 50V
C29: GRM0335C1H121JA01D | D29: 0.6 x 0.3(0201) | E29: 0.3mm | F29: COG | G29: -55 to 125℃ | H29: 121 | I29: ±5 % | J29: 50V
C30: GRM0335C1H181JA01D | D30: 0.6 x 0.3(0201) | E30: 0.3mm | F30: COG | G30: -55 to 125℃ | H30: 181 | I30: ±5 % | J30: 50V
C31: GRM0335C1H181JA01D | D31: 0.6 x 0.3(0201) | E31: 0.3mm | F31: COG | G31: -55 to 125℃ | H31: 181 | I31: ±5 % | J31: 50V
A32: CL03A224KP3NNNC | C32: GRM033R61A224KE90D | D32: 0.6 x 0.3(0201) | E32: 0.3mm | F32: X5R | G32: -55 to 85℃ | H32: 224 | I32: ±10 % | J32: 10V
A33: CL03A224KQ3NNNC | B33: JMK063BJ224KP-F | C33: GRM033R60J224KE15D | D33: 0.6 x 0.3(0201) | E33: 0.3mm | F33: X5R | G33: -55 to 85℃ | H33: 224 | I33: ±10 % | J33: 6.3V
C34: GRM033C80J224ME90D | D34: 0.6 x 0.3(0201) | E34: 0.3mm | F34: X6S | G34: -55 to 105℃ | H34: 224 | I34: ±20 % | J34: 6.3V
C35: GRM033R61A225KE47D | D35: 0.6 x 0.3(0201) | E35: 0.3mm | F35: X5R | G35: -55 to 85℃ | H35: 225 | I35: ±10 % | J35: 10V
A36: CL03A225MP3CRNC | B36: LDK063BBJ225MPLM9 | C36: GRM033R61A225ME47D | D36: 0.6 x 0.3(0201) | E36: 0.3mm | F36: X5R | G36: -55 to 85℃ | H36: 225 | I36: ±20 % | J36: 10V
C37: GRM033D80E225ME47D | D37: 0.6 x 0.3(0201) | E37: 0.3mm | F37: X6T | G37: -55 to 105℃ | H37: 225 | I37: ±20 % | J37: 2.5V
C38: GRM033R60G225ME44D | D38: 0.6 x 0.3(0201) | E38: 0.3mm | F38: X5R | G38: -55 to 85℃ | H38: 225 | I38: ±20 % | J38: 4V
C39: GRM033R60G225ME47D | D39: 0.6 x 0.3(0201) | E39: 0.3mm | F39: X5R | G39: -55 to 85℃ | H39: 225 | I39: ±20 % | J39: 4V
D40: 0.6 x 0.3(0201) | E40: 0.35mm | F40: X5R | G40: -55 to 85℃ | H40: 225 | I40: ±20 % | J40: 6.3V
...

Sheet 3~5月推廣重點物料(電原)
A1: TAIYO | B1: TDK | C1: Murata | D1: Kyocera | E1: Samsung | F1: YAGEO | G1: WALSIN | H1: Size L x Wmm (Inch) | I1: Thickness(mm) | J1: Temperature Characteristic | K1: Temp.Characteristic | L1: Capacitance | M1: Tolerance | N1: Rated Volt(Vdc) | O1: Remark | P1: L/T | Q1: MOQ
A2: EDK105BBJ475MVLF | H2: 1.0 x 0.5(0402) | I2: 0.5mm | J2: X5R | K2: -55 to 85℃ | L2: 475 | M2: ±20 % | N2: 16V
A3: EMK107BB7225KA-T | C3: GRM188R61C225KE15D | E3: CL10A225KO8NNNC | H3: 1.6 x 0.8 (0603) | I3: 0.8mm | J3: X5R | K3: -55 to 85℃ | L3: 225 | M3: ±10 % | N3: 16V
C4: GRM188R61E225KA12D | E4: CL10A225KA8NNNC | H4: 1.6 x 0.8 (0603) | I4: 0.8mm | J4: X5R | K4: -55 to 85℃ | L4: 225 | M4: ±10 % | N4: 25V
C5: GRM188R61H225KE11D | H5: 1.6 x 0.8 (0603) | I5: 0.8mm | J5: X5R | K5: -55 to 85℃ | L5: 225 | M5: ±10 % | N5: 50V
C6: GCM188R71E105KA64D | E6: CL10B105KA8NNNC | F6: CC0603KRX5R8BB105 | H6: 1.6 x 0.8 (0603) | I6: 0.8mm | J6: X7R | K6: -55 to 125℃ | L6: 105 | M6: ±10 % | N6: 25V
A7: EMK212BJ106KD-T | H7: 2.0 x 1.25 (0805) | I7: 0.85mm | J7: X5R | K7: -55 to 85℃ | L7: 106 | M7: ±10 % | N7: 16V | O7: 庫存
A8: TMK212BBJ106KG-T | C8: GRM21BR61E106MA73 | E8: CL21A106KAYNNNE | H8: 2.0 x 1.25 (0805) | I8: 1.25mm | J8: X5R | K8: -55 to 85℃ | L8: 106 | M8: ±10 % | N8: 25V | O8: 庫存
A9: LMK212BBJ226MD-T | H9: 2.0 x 1.25 (0805) | I9: 0.85mm | J9: X5R | K9: -55 to 85℃ | L9: 226 | M9: ±20 % | N9: 10V
C10: GRM21BR61E226ME44L | E10: CL21A226MAYNNNE | H10: 2.0 x 1.25 (0805) | I10: 1.25mm | J10: X5R | K10: -55 to 85℃ | L10: 226 | M10: ±20 % | N10: 25V
A11: TMK212AB7475KG-T | E11: CL21A475KAQNNNE | H11: 2.0 x 1.25 (0805) | I11: 1.25mm | J11: X5R | K11: -55 to 85℃ | L11: 475 | M11: ±10 % | N11: 25V | O11: 庫存
A12: TMK212AB7475KG-T | E12: CL21A475KAQNNNE | H12: 2.0 x 1.25 (0805) | I12: 1.25mm | J12: X5R | K12: -55 to 85℃ | L12: 475 | M12: ±10 % | N12: 25V
C13: GRM21BR61H475KE51L | E13: CL21A475KBQNNNE | H13: 2.0 x 1.25 (0805) | I13: 1.25mm | J13: X5R | K13: -55 to 85℃ | L13: 475 | M13: ±10 % | N13: 50V
C14: GCM21BR72A104KA37L | E14: CL21B104KCFNNNE | H14: 2.0 x 1.25 (0805) | I14: 1.25mm | J14: X7R | K14: -55 to 125℃ | L14: 104 | M14: ±10 % | N14: 100V
C15: GRM21BR71E105KA99L | E15: CL21B105KAFNNNE | F15: CC0805KKX7R8BB105 | H15: 2.0 x 1.25 (0805) | I15: 1.25mm | J15: X7R | K15: -55 to 125℃ | L15: 105 | M15: ±10 % | N15: 25V
C16: GRM21BZ71C106KE15 | E16: CL21B106KOQNNNE | H16: 2.0 x 1.25 (0805) | I16: 1.25mm | J16: X7R | K16: -55 to 125℃ | L16: 106 | M16: ±10 % | N16: 16V
C17: GRM21BR71E225KE11L | E17: CL21B225KAFNNNE | H17: 2.0 x 1.25 (0805) | I17: 1.25mm | J17: X7R | K17: -55 to 125℃ | L17: 225 | M17: ±10 % | N17: 25V
C18: GRM21BR71E475KA73L | E18: CL21B475KAFNNNE | H18: 2.0 x 1.25 (0805) | I18: 1.25mm | J18: X7R | K18: -55 to 125℃ | L18: 475 | M18: ±10 % | N18: 25V | O18: 庫存
C19: GRM21BR71E475KA73L | E19: CL21B475KAFNNNE | H19: 2.0 x 1.25 (0805) | I19: 1.25mm | J19: X7R | K19: -55 to 125℃ | L19: 475 | M19: ±10 % | N19: 25V
C20: GCM21BR71E225KA73L | H20: 2.0 x 1.25 (0805) | I20: 1.25mm | J20: X7S | K20: -55 to 125℃ | L20: 225 | M20: ±10 % | N20: 25V
C21: GRM21BD71A226ME44L | H21: 2.0 x 1.25 (0805) | I21: 1.25mm | J21: X7T | K21: -55 to 125℃ | L21: 226 | M21: ±20 % | N21: 10V | O21: 庫存
E22: CL31A106KAHNNNE | H22: 3.2 x 1.6 (1206) | I22: 1.6mm | J22: X5R | K22: -55 to 85℃ | L22: 106 | M22: ±10 % | N22: 25V
C23: GRM31CR61E226KE15L | E23: CL31A226KAHNNNE | F23: CC1206KKX5R8BB226 | H23: 3.2 x 1.6 (1206) | I23: 1.6mm | J23: X5R | K23: -55 to 85℃ | L23: 226 | M23: ±10 % | N23: 25V | O23: 庫存
C24: GRM31CR71C106KAC7L | E24: CL31B106KOHNNNE | H24: 3.2 x 1.6 (1206) | I24: 1.6mm | J24: X7R | K24: -55 to 125℃ | L24: 106 | M24: ±10 % | N24: 16V
C25: GRM31CR71E106KA12L | E25: CL31B106KAHNNNE | H25: 3.2 x 1.6 (1206) | I25: 1.6mm | J25: X7R | K25: -55 to 125℃ | L25: 106 | M25: ±10 % | N25: 25V
C26: GCM31CR71H225KA55L | E26: CL31B225KBHNNNE | H26: 3.2 x 1.6 (1206) | I26: 1.6mm | J26: X7R | K26: -55 to 125℃ | L26: 225 | M26: ±10 % | N26: 50V
C27: GRM31CR71H475KA12L | E27: CL31B475KBHNNNE | H27: 3.2 x 1.6 (1206) | I27: 1.6mm | J27: X7R | K27: -55 to 125℃ | L27: 475 | M27: ±10 % | N27: 50V
C28: GCM31CC71H475KA03L | H28: 3.2 x 1.6 (1206) | I28: 1.6mm | J28: X7S | K28: -55 to 125℃ | L28: 475 | M28: ±10 % | N28: 50V | O28: 庫存
C29: GRM32DR71E106KA12L | E29: CL32B106KAJNNNE | H29: 3.2 x 2.5 (1210) | I29: 2.0mm | J29: X7R | K29: -55 to 125℃ | L29: 106 | M29: ±10 % | N29: 25V
E30: CL31A476MQHNNNE | H30: 3.2 x 1.6 (1206) | I30: 1.6mm | J30: X5R | K30: -55 to 85℃ | L30: 476 | M30: ±10 % | N30: 6.3V
E31: CL32B226KAJNNNE | H31: 3.2 x 2.5 (1210) | I31: 2.5mm | J31: X7R | K31: -55 to 125℃ | L31: 226 | M31: ±10 % | N31: 25V

Sheet 3~5月推廣重點物料(消費類)
A1: TAIYO | B1: TDK | C1: Murata | D1: Kyocera | E1: Samsung | F1: YAGEO | G1: WALSIN | H1: Size L x Wmm (Inch) | I1: Thickness(mm) | J1: Temperature Characteristic | K1: Temp.Characteristic | L1: Capacitance | M1: Tolerance | N1: Rated Volt(Vdc)
C2: GRM155R71H104KE14D | E2: CL05B104KB5NNNC | H2: 1.0 x 0.5(0402) | I2: 0.5mm | J2: X7R | K2: -55 to 125℃ | L2: 104 | M2: ±10 % | N2: 50V
A3: EMK063BJ104KP-F | E3: CL03A104KO3NNNC | H3: 0.6 x 0.3(0201) | I3: 0.3mm | J3: X5R | K3: -55 to 85℃ | L3: 104 | M3: ±10 % | N3: 16V
C4: GRM033C81C104KE14D | H4: 0.6 x 0.3(0201) | I4: 0.3mm | J4: X6S | K4: -55 to 105℃ | L4: 104 | M4: ±10 % | N4: 16V
C5: GRM033R61E104KE14D | E5: CL03A104KA3NNNC | H5: 0.6 x 0.3(0201) | I5: 0.3mm | J5: X5R | K5: -55 to 85℃ | L5: 104 | M5: ±10 % | N5: 25V
A6: JMK063ABJ105KP-F | C6: GRM033R60J105KEA2D | E6: CL03A105KQ3CSNC | H6: 0.6 x 0.3(0201) | I6: 0.3mm | J6: X5R | K6: -55 to 85℃ | L6: 105 | M6: ±10 % | N6: 6.3V
A7: JDK063BJ105MP-FD | C7: GRM033R60J105MEA2D | E7: CL03A105MQ3CSNC | H7: 0.6 x 0.3(0201) | I7: 0.3mm | J7: X5R | K7: -55 to 85℃ | L7: 105 | M7: ±20 % | N7: 6.3V
A8: LDK063ABJ105MP-F | C8: GRM033R61A105ME44D | E8: CL03A105MP3NSNC | H8: 0.6 x 0.3(0201) | I8: 0.3mm | J8: X5R | K8: -55 to 85℃ | L8: 105 | M8: ±20 % | N8: 10V
A9: LDK063BBJ225MPLM9 | C9: GRM033R61A225ME47D | D9: CM03X5R225M10AH | E9: CL03A225MP3CRNC | H9: 0.6 x 0.3(0201) | I9: 0.3mm | J9: X5R | K9: -55 to 85℃ | L9: 225 | M9: ±20 % | N9: 10V
C10: GRM033R60J225ME47D | D10: CM03X5R225M06AH | E10: CL03A225MQ3CRNC | H10: 0.6 x 0.3(0201) | I10: 0.3mm | J10: X5R | K10: -55 to 85℃ | L10: 225 | M10: ±20 % | N10: 6.3V
D11: CM03X5R475M06AH | H11: 0.6 x 0.3(0201) | J11: X5R | K11: -55 to 85℃ | L11: 475 | M11: ±20 % | N11: 6.3V
C12: GRM033R61A225KE47D | H12: 0.6 x 0.3(0201) | I12: 0.3mm | J12: X5R | K12: -55 to 85℃ | L12: 225 | M12: ±10 % | N12: 10V
A13: EMK105B7104KV-F | C13: GRM155R71C104KA88D | E13: CL05B104KO5NNNC | G13: 0402B104K160CT | H13: 1.0 x 0.5(0402) | I13: 0.5mm | J13: X7R | K13: -55 to 125℃ | L13: 104 | M13: ±10 % | N13: 16V
A14: LMK105BJ105KV-F | C14: GRM155R61A105KE*** | E14: CL05A105KP5NNNC | G14: 0402X105K100CTNB | H14: 1.0 x 0.5(0402) | I14: 0.5mm | J14: X5R | K14: -55 to 85℃ | L14: 105 | M14: ±10 % | N14: 10V
A15: EMK105BJ105KV-F | C15: GRM155R61C105KA12D | E15: CL05A105KO5NNNC | H15: 1.0 x 0.5(0402) | I15: 0.5mm | J15: X5R | K15: -55 to 85℃ | L15: 105 | M15: ±10 % | N15: 16V
A16: TMK105BJ105KV-F | E16: CL05A105KA5NQNC | H16: 1.0 x 0.5(0402) | I16: 0.5mm | J16: X5R | K16: -55 to 85℃ | L16: 105 | M16: ±10 % | N16: 25V
C17: GRM155R61H105KE05D | H17: 1.0 x 0.5(0402) | I17: 0.5mm | J17: X5R | K17: -55 to 85℃ | L17: 105 | M17: ±10 % | N17: 50V
A18: JMK105BJ105KV-F | C18: GRM155R60J105KE17D | E18: CL05A105KQ5NNNC | G18: 0402B105K6R3CT | H18: 1.0 x 0.5(0402) | I18: 0.5mm | J18: X5R | K18: -55 to 85℃ | L18: 105 | M18: ±10 % | N18: 6.3V
A19: LMK105BJ225KV-F | C19: GRM155R61A225KE95D | E19: CL05A225KP5NSNC | H19: 1.0 x 0.5(0402) | I19: 0.5mm | J19: X5R | K19: -55 to 85℃ | L19: 225 | M19: ±10 % | N19: 10V
C20: GRM155C71A225KE11D | H20: 1.0 x 0.5(0402) | I20: 0.5mm | J20: X7S | K20: -55 to 125℃ | L20: 225 | M20: ±20 % | N20: 10V
A21: EMK105ABJ225KV-F | H21: 1.0 x 0.5(0402) | I21: 0.5mm | J21: X5R | K21: -55 to 85℃ | L21: 225 | M21: ±10 % | N21: 16V
A22: TMK107ABJ225KA-T | C22: GRM155R61E225KE11D | E22: CL05A225KA5NUNC | H22: 1.0 x 0.5(0402) | I22: 0.5mm | J22: X5R | K22: -55 to 85℃ | L22: 225 | M22: ±10 % | N22: 25V
C23: GRM155C80J225KE95D | H23: 1.0 x 0.5(0402) | I23: 0.5mm | J23: X6S | K23: -55 to 105℃ | L23: 225 | M23: ±10 % | N23: 6.3V
C24: GRM155R60J225ME15D | E24: CL05A225MQ5NSNC | H24: 1.0 x 0.5(0402) | I24: 0.5mm | J24: X5R | K24: -55 to 85℃ | L24: 225 | M24: ±20 % | N24: 6.3V
D25: CM05X5R226M06AH | H25: 1.0 x 0.5(0402) | J25: X5R | K25: -55 to 85℃ | L25: 226 | M25: ±20 % | N25: 6.3v
A26: EDK105BBJ475MVLF | H26: 1.0 x 0.5(0402) | I26: 0.5mm | J26: X5R | K26: -55 to 85℃ | L26: 475 | M26: ±20 % | N26: 16V
A27: JMK105BJ475MV-FD | C27: GRM155R60J475ME87 | E27: CL05A475MQ5NRNC | F27: CC0402MRX5R5BB475 | H27: 1.0 x 0.5(0402) | I27: 0.5mm | J27: X5R | K27: -55 to 85℃ | L27: 475 | M27: ±20 % | N27: 6.3V
A28: JMK105CBJ106MV-F | C28: GRM155R60J106ME05D | E28: CL05A106MQ5NUNC | H28: 1.0 x 0.5(0402) | I28: 0.5mm | J28: X5R | K28: -55 to 85℃ | L28: 106 | M28: ±20 % | N28: 6.3V
A29: LDK105CBJ106MVLF | C29: GRM155R61A106ME11D | E29: CL05A106MP5NUNC | H29: 1.0 x 0.5(0402) | I29: 0.5mm | J29: X5R | K29: -55 to 85℃ | L29: 106 | M29: ±20 % | N29: 10V
E30: CL10B104KB8NNNC | G30: 0603B104K500CT | H30: 1.6 x 0.8 (0603) | I30: 0.8mm | J30: X7R | K30: -55 to 125℃ | L30: 104 | M30: ±10 % | N30: 50V
C31: GRM188R61E105KA12D | E31: CL10A105KA8NNNC | G31: 0603X105K250CT | H31: 1.6 x 0.8 (0603) | I31: 0.8mm | J31: X5R | K31: -55 to 85℃ | L31: 105 | M31: ±10 % | N31: 25V
C32: GCM188R71E105KA64D | E32: CL10B105KA8NNNC | F32: CC0603KRX5R8BB105 | H32: 1.6 x 0.8 (0603) | I32: 0.8mm | J32: X7R | K32: -55 to 125℃ | L32: 105 | M32: ±10 % | N32: 25V
C33: GRM188R71A225KE15D | H33: 1.6 x 0.8 (0603) | I33: 0.8mm | J33: X7R | K33: -55 to 125℃ | L33: 225 | M33: ±10 % | N33: 10V
A34: EMK107BB7225KA-T | C34: GRM188R61C225KE15D | E34: CL10A225KO8NNNC | H34: 1.6 x 0.8 (0603) | I34: 0.8mm | J34: X5R | K34: -55 to 85℃ | L34: 225 | M34: ±10 % | N34: 16V
C35: GRM188R61E225KA12D | E35: CL10A225KA8NNNC | H35: 1.6 x 0.8 (0603) | I35: 0.8mm | J35: X5R | K35: -55 to 85℃ | L35: 225 | M35: ±10 % | N35: 25V
C36: GRM188R61H225KE11D | H36: 1.6 x 0.8 (0603) | I36: 0.8mm | J36: X5R | K36: -55 to 85℃ | L36: 225 | M36: ±10 % | N36: 50V
A37: LDK107BBJ226MA-R | E37: CL10A226MP8NUNE | H37: 1.6 x 0.8 (0603) | I37: 0.8mm | J37: X5R | K37: -55 to 85℃ | L37: 226 | M37: ±20 % | N37: 10V
A38: LDK107BJ475KA-T | C38: GRM188R61A475KE15D | E38: CL10A475KP8NNN* | H38: 1.6 x 0.8 (0603) | I38: 0.8mm | J38: X5R | K38: -55 to 85℃ | L38: 475 | M38: ±10 % | N38: 10V
C39: GRM188R60J475KE*** | E39: CL10A475KQ8NNN* | H39: 1.6 x 0.8 (0603) | I39: 0.8mm | J39: X5R | K39: -55 to 85℃ | L39: 475 | M39: ±10 % | N39: 6.3V
A40: LMK107BJ106KALTD | C40: GRM188R61A106KE69D | E40: CL10A106KP8NNNC | H40: 1.6 x 0.8 (0603) | I40: 0.8mm | J40: X5R | K40: -55 to 85℃ | L40: 106 | M40: ±10 % | N40: 10V
...

Sheet MLCC 所有品牌資訊匯總
A1: TAIYO | B1: TDK | C1: Murata | D1: Kyocera | E1: Samsung | F1: YAGEO | G1: WALSIN | H1: Size L x Wmm (Inch) | I1: Thickness(mm) | J1: Temperature Characteristic | K1: Temp.Characteristic | L1: Capacitance | M1: Tolerance | N1: Rated Volt(Vdc) | O1: Remark | P1: L/T | Q1: MOQ
C2: GRM0335C1H2R0BA01D | H2: 0.6 x 0.3(0201) | I2: 0.3mm | J2: COG | K2: -55 to 125℃ | L2: 2R0 | M2: ±0.1pF | N2: 50V
C3: GRM0335C1H4R7BA01D | H3: 0.6 x 0.3(0201) | I3: 0.3mm | J3: COG | K3: -55 to 125℃ | L3: 4R7 | M3: ±0.1pF | N3: 50V
C4: GRM0335C1H101JA01D | E4: CL03C470JB3NNNC | H4: 0.6 x 0.3(0201) | I4: 0.3mm | J4: COG | K4: -55 to 125℃ | L4: 101 | M4: ±5 % | N4: 50V
C5: GRM0335C1H101JA01D | E5: CL03C330JB3NNNC | H5: 0.6 x 0.3(0201) | I5: 0.3mm | J5: COG | K5: -55 to 125℃ | L5: 101 | M5: ±5 % | N5: 50V
C6: GRM033R71E103KE14D | H6: 0.6 x 0.3(0201) | I6: 0.3mm | J6: X7R | K6: -55 to 125℃ | L6: 103 | M6: ±10 % | N6: 25V
C7: GRM033R71E103KE14D | E7: CL03C101JB3NNNC | H7: 0.6 x 0.3(0201) | I7: 0.3mm | J7: X7R | K7: -55 to 125℃ | L7: 103 | M7: ±10 % | N7: 50V
A8: LMK063BJ104KP-F | E8: CL03A104KP3NNNC | H8: 0.6 x 0.3(0201) | I8: 0.3mm | J8: X5R | K8: -55 to 85℃ | L8: 104 | M8: ±10 % | N8: 10V
A9: EMK063BJ104KP-F | E9: CL03A104KO3NNNC | H9: 0.6 x 0.3(0201) | I9: 0.3mm | J9: X5R | K9: -55 to 85℃ | L9: 104 | M9: ±10 % | N9: 16V
C10: GRM033C81C104KE14D | H10: 0.6 x 0.3(0201) | I10: 0.3mm | J10: X6S | K10: -55 to 105℃ | L10: 104 | M10: ±10 % | N10: 16V
A11: TMK063ABJ104KP-F | C11: GRM033R61E104KE14D | E11: CL03A104KA3NNNC | H11: 0.6 x 0.3(0201) | I11: 0.3mm | J11: X5R | K11: -55 to 85℃ | L11: 104 | M11: ±10 % | N11: 25V
C12: GRM033R60J104KE19D | E12: CL03A104KQ3NNNC | H12: 0.6 x 0.3(0201) | I12: 0.3mm | J12: X5R | K12: -55 to 85℃ | L12: 104 | M12: ±10 % | N12: 6.3V
A13: LDK063ABJ105MP-F | C13: GRM033R61A105ME44D | E13: CL03A105MP3NSNC | H13: 0.6 x 0.3(0201) | I13: 0.3mm | J13: X5R | K13: -55 to 85℃ | L13: 105 | M13: ±20 % | N13: 10V
C14: GRM033R61A105ME15D | H14: 0.6 x 0.3(0201) | I14: 0.3mm | J14: X5R | K14: -55 to 85℃ | L14: 105 | M14: ±20 % | N14: 10V
C15: GRM033C81A105ME05D | H15: 0.6 x 0.3(0201) | I15: 0.3mm | J15: X6S | K15: -55 to 105℃ | L15: 105 | M15: ±20 % | N15: 10V
C16: GRM033R61C105ME15D | E16: CL03A105MO3NRNC | H16: 0.6 x 0.3(0201) | I16: 0.3mm | J16: X5R | K16: -55 to 85℃ | L16: 105 | M16: ±20 % | N16: 16V
C17: GRM033D70E105ME15D | H17: 0.6 x 0.3(0201) | I17: 0.3mm | J17: X7T | K17: -55 to 125℃ | L17: 105 | M17: ±20 % | N17: 2.5V
C18: GRM033C81E105KE14# | H18: 0.6 x 0.3(0201) | I18: 0.3mm | J18: X6S | K18: =VLOOKUP(J18,材質!A:B,2,0) -> -55 to 105℃ | L18: 105 | M18: ±10 % | N18: 25V
C19: GRM032R60G105ME05D | H19: 0.6 x 0.3(0201) | I19: 0.2mm | J19: X5R | K19: -55 to 85℃ | L19: 105 | M19: ±20 % | N19: 4V
C20: GRM033R60G105MEA2D | E20: CL03A105MR3CSNC | H20: 0.6 x 0.3(0201) | I20: 0.3mm | J20: X5R | K20: -55 to 85℃ | L20: 105 | M20: ±20 % | N20: 4V
C21: GRM033C80G105ME05* | H21: 0.6 x 0.3(0201) | I21: 0.3mm | J21: X6S | K21: -55 to 105℃ | L21: 105 | M21: ±20 % | N21: 4V
C22: GRM032D80G105ME01D | H22: 0.6 x 0.3(0201) | I22: 0.2mm | J22: X6T | K22: -55 to 105℃ | L22: 105 | M22: ±20 % | N22: 4V
C23: GRM033D70G105ME01D | H23: 0.6 x 0.3(0201) | I23: 0.3mm | J23: X7T | K23: -55 to 125℃ | L23: 105 | M23: ±20 % | N23: 4V
A24: JMK063ABJ105KP-F | C24: GRM033R60J105KEA2D | E24: CL03A105KQ3CSNC | H24: 0.6 x 0.3(0201) | I24: 0.3mm | J24: X5R | K24: -55 to 85℃ | L24: 105 | M24: ±10 % | N24: 6.3V
A25: JDK063ABJ105KP-F | H25: 0.6 x 0.3(0201) | I25: 0.3mm | J25: X5R | K25: -55 to 85℃ | L25: 105 | M25: ±10 % | N25: 6.3V
A26: JDK063BJ105MP-FD | C26: GRM033R60J105MEA2D | E26: CL03A105MQ3CSNC | H26: 0.6 x 0.3(0201) | I26: 0.3mm | J26: X5R | K26: -55 to 85℃ | L26: 105 | M26: ±20 % | N26: 6.3V
A27: JMK063ABJ105MP-F | H27: 0.6 x 0.3(0201) | I27: 0.3mm | J27: X5R | K27: -55 to 85℃ | L27: 105 | M27: ±20 % | N27: 6.3V
C28: GRM033C80J105ME05D | H28: 0.6 x 0.3(0201) | I28: 0.3mm | J28: X6S | K28: -55 to 105℃ | L28: 105 | M28: ±20 % | N28: 6.3V
C29: GRM033D70J105ME01D | H29: 0.6 x 0.3(0201) | I29: 0.3mm | J29: X7T | K29: -55 to 125℃ | L29: 105 | M29: ±20 % | N29: 6.3V
C30: GRM0335C1H121JA01D | H30: 0.6 x 0.3(0201) | I30: 0.3mm | J30: COG | K30: -55 to 125℃ | L30: 121 | M30: ±5 % | N30: 50V
C31: GRM0335C1H121JA01D | H31: 0.6 x 0.3(0201) | I31: 0.3mm | J31: COG | K31: -55 to 125℃ | L31: 121 | M31: ±5 % | N31: 50V
C32: GRM0335C1H181JA01D | H32: 0.6 x 0.3(0201) | I32: 0.3mm | J32: COG | K32: -55 to 125℃ | L32: 181 | M32: ±5 % | N32: 50V
C33: GRM0335C1H181JA01D | H33: 0.6 x 0.3(0201) | I33: 0.3mm | J33: COG | K33: -55 to 125℃ | L33: 181 | M33: ±5 % | N33: 50V
C34: GRM033R61A224KE90D | E34: CL03A224KP3NNNC | H34: 0.6 x 0.3(0201) | I34: 0.3mm | J34: X5R | K34: -55 to 85℃ | L34: 224 | M34: ±10 % | N34: 10V
A35: JMK063BJ224KP-F | C35: GRM033R60J224KE15D | E35: CL03A224KQ3NNNC | H35: 0.6 x 0.3(0201) | I35: 0.3mm | J35: X5R | K35: -55 to 85℃ | L35: 224 | M35: ±10 % | N35: 6.3V
C36: GRM033C80J224ME90D | H36: 0.6 x 0.3(0201) | I36: 0.3mm | J36: X6S | K36: -55 to 105℃ | L36: 224 | M36: ±20 % | N36: 6.3V
C37: GRM033R61A225KE47D | D37: CM03X5R225K10AH | H37: 0.6 x 0.3(0201) | I37: 0.3mm | J37: X5R | K37: -55 to 85℃ | L37: 225 | M37: ±10 % | N37: 10V
A38: LDK063BBJ225MPLM9 | C38: GRM033R61A225ME47D | D38: CM03X5R225M10AH | E38: CL03A225MP3CRNC | H38: 0.6 x 0.3(0201) | I38: 0.3mm | J38: X5R | K38: -55 to 85℃ | L38: 225 | M38: ±20 % | N38: 10V
C39: GRM033D80E225ME47D | H39: 0.6 x 0.3(0201) | I39: 0.3mm | J39: X6T | K39: -55 to 105℃ | L39: 225 | M39: ±20 % | N39: 2.5V
C40: GRM033R60G225ME44D | H40: 0.6 x 0.3(0201) | I40: 0.3mm | J40: X5R | K40: -55 to 85℃ | L40: 225 | M40: ±20 % | N40: 4V
...

Sheet 7月可擴賣物料規格
A1: Murata | B1: TAIYO | C1: Kyocera | D1: 尺寸 | E1: 厚度 | F1: 材質 | G1: 溫度係數 | H1: 容質 | I1: 精度 | J1: 耐壓
A2: GRM033C81C104KE14D | D2: =VLOOKUP(A2,'MLCC 所有品牌資訊匯總'!$C:$N,6,0) -> 0.6 x 0.3(0201) | E2: =VLOOKUP(A2,'MLCC 所有品牌資訊匯總'!$C:$N,7,0) -> 0.3mm | F2: =VLOOKUP(A2,'MLCC 所有品牌資訊匯總'!$C:$N,8,0) -> X6S | G2: =VLOOKUP(A2,'MLCC 所有品牌資訊匯總'!$C:$N,9,0) -> -55 to 105℃ | H2: =VLOOKUP(A2,'MLCC 所有品牌資訊匯總'!$C:$N,10,0) -> 104 | I2: =VLOOKUP(A2,'MLCC 所有品牌資訊匯總'!$C:$N,11,0) -> ±10 % | J2: =VLOOKUP(A2,'MLCC 所有品牌資訊匯總'!$C:$N,12,0) -> 16V
A3: GRM033R61A224KE90D | D3: =VLOOKUP(A3,'MLCC 所有品牌資訊匯總'!$C:$N,6,0) -> 0.6 x 0.3(0201) | E3: =VLOOKUP(A3,'MLCC 所有品牌資訊匯總'!$C:$N,7,0) -> 0.3mm | F3: =VLOOKUP(A3,'MLCC 所有品牌資訊匯總'!$C:$N,8,0) -> X5R | G3: =VLOOKUP(A3,'MLCC 所有品牌資訊匯總'!$C:$N,9,0) -> -55 to 85℃ | H3: =VLOOKUP(A3,'MLCC 所有品牌資訊匯總'!$C:$N,10,0) -> 224 | I3: =VLOOKUP(A3,'MLCC 所有品牌資訊匯總'!$C:$N,11,0) -> ±10 % | J3: =VLOOKUP(A3,'MLCC 所有品牌資訊匯總'!$C:$N,12,0) -> 10V
A4: GRM033R61A105ME44D | D4: =VLOOKUP(A4,'MLCC 所有品牌資訊匯總'!$C:$N,6,0) -> 0.6 x 0.3(0201) | E4: =VLOOKUP(A4,'MLCC 所有品牌資訊匯總'!$C:$N,7,0) -> 0.3mm | F4: =VLOOKUP(A4,'MLCC 所有品牌資訊匯總'!$C:$N,8,0) -> X5R | G4: =VLOOKUP(A4,'MLCC 所有品牌資訊匯總'!$C:$N,9,0) -> -55 to 85℃ | H4: =VLOOKUP(A4,'MLCC 所有品牌資訊匯總'!$C:$N,10,0) -> 105 | I4: =VLOOKUP(A4,'MLCC 所有品牌資訊匯總'!$C:$N,11,0) -> ±20 % | J4: =VLOOKUP(A4,'MLCC 所有品牌資訊匯總'!$C:$N,12,0) -> 10V
A5: GRM033R60J225ME47D | D5: =VLOOKUP(A5,'MLCC 所有品牌資訊匯總'!$C:$N,6,0) -> 0.6 x 0.3(0201) | E5: =VLOOKUP(A5,'MLCC 所有品牌資訊匯總'!$C:$N,7,0) -> 0.3mm | F5: =VLOOKUP(A5,'MLCC 所有品牌資訊匯總'!$C:$N,8,0) -> X5R | G5: =VLOOKUP(A5,'MLCC 所有品牌資訊匯總'!$C:$N,9,0) -> -55 to 85℃ | H5: =VLOOKUP(A5,'MLCC 所有品牌資訊匯總'!$C:$N,10,0) -> 225 | I5: =VLOOKUP(A5,'MLCC 所有品牌資訊匯總'!$C:$N,11,0) -> ±20 % | J5: =VLOOKUP(A5,'MLCC 所有品牌資訊匯總'!$C:$N,12,0) -> 6.3V
A6: GRM033R61A225KE47D | D6: =VLOOKUP(A6,'MLCC 所有品牌資訊匯總'!$C:$N,6,0) -> 0.6 x 0.3(0201) | E6: =VLOOKUP(A6,'MLCC 所有品牌資訊匯總'!$C:$N,7,0) -> 0.3mm | F6: =VLOOKUP(A6,'MLCC 所有品牌資訊匯總'!$C:$N,8,0) -> X5R | G6: =VLOOKUP(A6,'MLCC 所有品牌資訊匯總'!$C:$N,9,0) -> -55 to 85℃ | H6: =VLOOKUP(A6,'MLCC 所有品牌資訊匯總'!$C:$N,10,0) -> 225 | I6: =VLOOKUP(A6,'MLCC 所有品牌資訊匯總'!$C:$N,11,0) -> ±10 % | J6: =VLOOKUP(A6,'MLCC 所有品牌資訊匯總'!$C:$N,12,0) -> 10V
A7: GCM155C71A105KE38D | D7: =VLOOKUP(A7,'MLCC 所有品牌資訊匯總'!$C:$N,6,0) -> 1.0 x 0.5(0402) | E7: =VLOOKUP(A7,'MLCC 所有品牌資訊匯總'!$C:$N,7,0) -> 0.5mm | F7: =VLOOKUP(A7,'MLCC 所有品牌資訊匯總'!$C:$N,8,0) -> X7S | G7: =VLOOKUP(A7,'MLCC 所有品牌資訊匯總'!$C:$N,9,0) -> -55 to 125℃ | H7: =VLOOKUP(A7,'MLCC 所有品牌資訊匯總'!$C:$N,10,0) -> 105 | I7: =VLOOKUP(A7,'MLCC 所有品牌資訊匯總'!$C:$N,11,0) -> ±10 % | J7: =VLOOKUP(A7,'MLCC 所有品牌資訊匯總'!$C:$N,12,0) -> 10V
A8: GRM155R61H105KE05D | D8: =VLOOKUP(A8,'MLCC 所有品牌資訊匯總'!$C:$N,6,0) -> 1.0 x 0.5(0402) | E8: =VLOOKUP(A8,'MLCC 所有品牌資訊匯總'!$C:$N,7,0) -> 0.5mm | F8: =VLOOKUP(A8,'MLCC 所有品牌資訊匯總'!$C:$N,8,0) -> X5R | G8: =VLOOKUP(A8,'MLCC 所有品牌資訊匯總'!$C:$N,9,0) -> -55 to 85℃ | H8: =VLOOKUP(A8,'MLCC 所有品牌資訊匯總'!$C:$N,10,0) -> 105 | I8: =VLOOKUP(A8,'MLCC 所有品牌資訊匯總'!$C:$N,11,0) -> ±10 % | J8: =VLOOKUP(A8,'MLCC 所有品牌資訊匯總'!$C:$N,12,0) -> 50V
A9: GRM155R61E225KE11D | D9: =VLOOKUP(A9,'MLCC 所有品牌資訊匯總'!$C:$N,6,0) -> 1.0 x 0.5(0402) | E9: =VLOOKUP(A9,'MLCC 所有品牌資訊匯總'!$C:$N,7,0) -> 0.5mm | F9: =VLOOKUP(A9,'MLCC 所有品牌資訊匯總'!$C:$N,8,0) -> X5R | G9: =VLOOKUP(A9,'MLCC 所有品牌資訊匯總'!$C:$N,9,0) -> -55 to 85℃ | H9: =VLOOKUP(A9,'MLCC 所有品牌資訊匯總'!$C:$N,10,0) -> 225 | I9: =VLOOKUP(A9,'MLCC 所有品牌資訊匯總'!$C:$N,11,0) -> ±10 % | J9: =VLOOKUP(A9,'MLCC 所有品牌資訊匯總'!$C:$N,12,0) -> 25V
A10: GRM155R60J106ME05D | B10: JMK105CBJ106MV-F | D10: =VLOOKUP(A10,'MLCC 所有品牌資訊匯總'!$C:$N,6,0) -> 1.0 x 0.5(0402) | E10: =VLOOKUP(A10,'MLCC 所有品牌資訊匯總'!$C:$N,7,0) -> 0.5mm | F10: =VLOOKUP(A10,'MLCC 所有品牌資訊匯總'!$C:$N,8,0) -> X5R | G10: =VLOOKUP(A10,'MLCC 所有品牌資訊匯總'!$C:$N,9,0) -> -55 to 85℃ | H10: =VLOOKUP(A10,'MLCC 所有品牌資訊匯總'!$C:$N,10,0) -> 106 | I10: =VLOOKUP(A10,'MLCC 所有品牌資訊匯總'!$C:$N,11,0) -> ±20 % | J10: =VLOOKUP(A10,'MLCC 所有品牌資訊匯總'!$C:$N,12,0) -> 6.3V
A11: GRM155R60J226ME69D | C11: CM05X5R226M06AH | D11: =VLOOKUP(C11,'MLCC 所有品牌資訊匯總'!$D:$N,5,0) -> 1.0 x 0.5(0402) | F11: =VLOOKUP(C11,'MLCC 所有品牌資訊匯總'!$D:$N,7,0) -> X5R | G11: =VLOOKUP(C11,'MLCC 所有品牌資訊匯總'!$D:$N,8,0) -> -55 to 85℃ | H11: =VLOOKUP(C11,'MLCC 所有品牌資訊匯總'!$D:$N,9,0) -> 226 | I11: =VLOOKUP(C11,'MLCC 所有品牌資訊匯總'!$D:$N,10,0) -> ±20 % | J11: =VLOOKUP(C11,'MLCC 所有品牌資訊匯總'!$D:$N,11,0) -> 6.3v
A12: GRM188R61E105KA12D | D12: =VLOOKUP(A12,'MLCC 所有品牌資訊匯總'!$C:$N,6,0) -> 1.6 x 0.8 (0603) | E12: =VLOOKUP(A12,'MLCC 所有品牌資訊匯總'!$C:$N,7,0) -> 0.8mm | F12: =VLOOKUP(A12,'MLCC 所有品牌資訊匯總'!$C:$N,8,0) -> X5R | G12: =VLOOKUP(A12,'MLCC 所有品牌資訊匯總'!$C:$N,9,0) -> -55 to 85℃ | H12: =VLOOKUP(A12,'MLCC 所有品牌資訊匯總'!$C:$N,10,0) -> 105 | I12: =VLOOKUP(A12,'MLCC 所有品牌資訊匯總'!$C:$N,11,0) -> ±10 % | J12: =VLOOKUP(A12,'MLCC 所有品牌資訊匯總'!$C:$N,12,0) -> 25V
A13: GRM188R61H225KE11D | D13: =VLOOKUP(A13,'MLCC 所有品牌資訊匯總'!$C:$N,6,0) -> 1.6 x 0.8 (0603) | E13: =VLOOKUP(A13,'MLCC 所有品牌資訊匯總'!$C:$N,7,0) -> 0.8mm | F13: =VLOOKUP(A13,'MLCC 所有品牌資訊匯總'!$C:$N,8,0) -> X5R | G13: =VLOOKUP(A13,'MLCC 所有品牌資訊匯總'!$C:$N,9,0) -> -55 to 85℃ | H13: =VLOOKUP(A13,'MLCC 所有品牌資訊匯總'!$C:$N,10,0) -> 225 | I13: =VLOOKUP(A13,'MLCC 所有品牌資訊匯總'!$C:$N,11,0) -> ±10 % | J13: =VLOOKUP(A13,'MLCC 所有品牌資訊匯總'!$C:$N,12,0) -> 50V
A14: GRM188R61A106ME69D | D14: =VLOOKUP(A14,'MLCC 所有品牌資訊匯總'!$C:$N,6,0) -> 1.6 x 0.8 (0603) | E14: =VLOOKUP(A14,'MLCC 所有品牌資訊匯總'!$C:$N,7,0) -> 0.8mm | F14: =VLOOKUP(A14,'MLCC 所有品牌資訊匯總'!$C:$N,8,0) -> X5R | G14: =VLOOKUP(A14,'MLCC 所有品牌資訊匯總'!$C:$N,9,0) -> -55 to 85℃ | H14: =VLOOKUP(A14,'MLCC 所有品牌資訊匯總'!$C:$N,10,0) -> 106 | I14: =VLOOKUP(A14,'MLCC 所有品牌資訊匯總'!$C:$N,11,0) -> ±20 % | J14: =VLOOKUP(A14,'MLCC 所有品牌資訊匯總'!$C:$N,12,0) -> 10V
A15: GRM21BR71H105KA12L | D15: =VLOOKUP(A15,'MLCC 所有品牌資訊匯總'!$C:$N,6,0) -> 2.0 x 1.25 (0805) | E15: =VLOOKUP(A15,'MLCC 所有品牌資訊匯總'!$C:$N,7,0) -> 1.25mm | F15: =VLOOKUP(A15,'MLCC 所有品牌資訊匯總'!$C:$N,8,0) -> X7R | G15: =VLOOKUP(A15,'MLCC 所有品牌資訊匯總'!$C:$N,9,0) -> -55 to 125℃ | H15: =VLOOKUP(A15,'MLCC 所有品牌資訊匯總'!$C:$N,10,0) -> 105 | I15: =VLOOKUP(A15,'MLCC 所有品牌資訊匯總'!$C:$N,11,0) -> ±10 % | J15: =VLOOKUP(A15,'MLCC 所有品牌資訊匯總'!$C:$N,12,0) -> 50V
A16: GRM21BR71E225KE11L | D16: =VLOOKUP(A16,'MLCC 所有品牌資訊匯總'!$C:$N,6,0) -> 2.0 x 1.25 (0805) | E16: =VLOOKUP(A16,'MLCC 所有品牌資訊匯總'!$C:$N,7,0) -> 1.25mm | F16: =VLOOKUP(A16,'MLCC 所有品牌資訊匯總'!$C:$N,8,0) -> X7R | G16: =VLOOKUP(A16,'MLCC 所有品牌資訊匯總'!$C:$N,9,0) -> -55 to 125℃ | H16: =VLOOKUP(A16,'MLCC 所有品牌資訊匯總'!$C:$N,10,0) -> 225 | I16: =VLOOKUP(A16,'MLCC 所有品牌資訊匯總'!$C:$N,11,0) -> ±10 % | J16: =VLOOKUP(A16,'MLCC 所有品牌資訊匯總'!$C:$N,12,0) -> 25V
A17: GRM21BR61H475KE51L | D17: =VLOOKUP(A17,'MLCC 所有品牌資訊匯總'!$C:$N,6,0) -> 2.0 x 1.25 (0805) | E17: =VLOOKUP(A17,'MLCC 所有品牌資訊匯總'!$C:$N,7,0) -> 1.25mm | F17: =VLOOKUP(A17,'MLCC 所有品牌資訊匯總'!$C:$N,8,0) -> X5R | G17: =VLOOKUP(A17,'MLCC 所有品牌資訊匯總'!$C:$N,9,0) -> -55 to 85℃ | H17: =VLOOKUP(A17,'MLCC 所有品牌資訊匯總'!$C:$N,10,0) -> 475 | I17: =VLOOKUP(A17,'MLCC 所有品牌資訊匯總'!$C:$N,11,0) -> ±10 % | J17: =VLOOKUP(A17,'MLCC 所有品牌資訊匯總'!$C:$N,12,0) -> 50V
A18: GRM21BR61A476ME15L | B18: LMK212BBJ476MG | D18: =VLOOKUP(A18,'MLCC 所有品牌資訊匯總'!$C:$N,6,0) -> 2.0 x 1.25 (0805) | E18: =VLOOKUP(A18,'MLCC 所有品牌資訊匯總'!$C:$N,7,0) -> 1.25mm | F18: =VLOOKUP(A18,'MLCC 所有品牌資訊匯總'!$C:$N,8,0) -> X5R | G18: =VLOOKUP(A18,'MLCC 所有品牌資訊匯總'!$C:$N,9,0) -> -55 to 85℃ | H18: =VLOOKUP(A18,'MLCC 所有品牌資訊匯總'!$C:$N,10,0) -> 476 | I18: =VLOOKUP(A18,'MLCC 所有品牌資訊匯總'!$C:$N,11,0) -> ±20 % | J18: =VLOOKUP(A18,'MLCC 所有品牌資訊匯總'!$C:$N,12,0) -> 10V
A19: GRM31CR71E106KA12L | D19: =VLOOKUP(A19,'MLCC 所有品牌資訊匯總'!$C:$N,6,0) -> 3.2 x 1.6 (1206) | E19: =VLOOKUP(A19,'MLCC 所有品牌資訊匯總'!$C:$N,7,0) -> 1.6mm | F19: =VLOOKUP(A19,'MLCC 所有品牌資訊匯總'!$C:$N,8,0) -> X7R | G19: =VLOOKUP(A19,'MLCC 所有品牌資訊匯總'!$C:$N,9,0) -> -55 to 125℃ | H19: =VLOOKUP(A19,'MLCC 所有品牌資訊匯總'!$C:$N,10,0) -> 106 | I19: =VLOOKUP(A19,'MLCC 所有品牌資訊匯總'!$C:$N,11,0) -> ±10 % | J19: =VLOOKUP(A19,'MLCC 所有品牌資訊匯總'!$C:$N,12,0) -> 25V
A20: GRM31CR71H475KA12L | D20: =VLOOKUP(A20,'MLCC 所有品牌資訊匯總'!$C:$N,6,0) -> 3.2 x 1.6 (1206) | E20: =VLOOKUP(A20,'MLCC 所有品牌資訊匯總'!$C:$N,7,0) -> 1.6mm | F20: =VLOOKUP(A20,'MLCC 所有品牌資訊匯總'!$C:$N,8,0) -> X7R | G20: =VLOOKUP(A20,'MLCC 所有品牌資訊匯總'!$C:$N,9,0) -> -55 to 125℃ | H20: =VLOOKUP(A20,'MLCC 所有品牌資訊匯總'!$C:$N,10,0) -> 475 | I20: =VLOOKUP(A20,'MLCC 所有品牌資訊匯總'!$C:$N,11,0) -> ±10 % | J20: =VLOOKUP(A20,'MLCC 所有品牌資訊匯總'!$C:$N,12,0) -> 50V
A21: GRM31CR71A226KE15L | D21: =VLOOKUP(A21,'MLCC 所有品牌資訊匯總'!$C:$N,6,0) -> 3.2 x 1.6 (1206) | E21: =VLOOKUP(A21,'MLCC 所有品牌資訊匯總'!$C:$N,7,0) -> 1.6mm | F21: =VLOOKUP(A21,'MLCC 所有品牌資訊匯總'!$C:$N,8,0) -> X7R | G21: =VLOOKUP(A21,'MLCC 所有品牌資訊匯總'!$C:$N,9,0) -> -55 to 125℃ | H21: =VLOOKUP(A21,'MLCC 所有品牌資訊匯總'!$C:$N,10,0) -> 226 | I21: =VLOOKUP(A21,'MLCC 所有品牌資訊匯總'!$C:$N,11,0) -> ±10 % | J21: =VLOOKUP(A21,'MLCC 所有品牌資訊匯總'!$C:$N,12,0) -> 10V
A22: GRM32DR71E106KA12L | D22: =VLOOKUP(A22,'MLCC 所有品牌資訊匯總'!$C:$N,6,0) -> 3.2 x 2.5 (1210) | E22: =VLOOKUP(A22,'MLCC 所有品牌資訊匯總'!$C:$N,7,0) -> 2.0mm | F22: =VLOOKUP(A22,'MLCC 所有品牌資訊匯總'!$C:$N,8,0) -> X7R | G22: =VLOOKUP(A22,'MLCC 所有品牌資訊匯總'!$C:$N,9,0) -> -55 to 125℃ | H22: =VLOOKUP(A22,'MLCC 所有品牌資訊匯總'!$C:$N,10,0) -> 106 | I22: =VLOOKUP(A22,'MLCC 所有品牌資訊匯總'!$C:$N,11,0) -> ±10 % | J22: =VLOOKUP(A22,'MLCC 所有品牌資訊匯總'!$C:$N,12,0) -> 25V
A23: GRM32ER61C476KE15L | D23: =VLOOKUP(A23,'MLCC 所有品牌資訊匯總'!$C:$N,6,0) -> 3.2 x 2.5 (1210) | E23: =VLOOKUP(A23,'MLCC 所有品牌資訊匯總'!$C:$N,7,0) -> 2.5mm | F23: =VLOOKUP(A23,'MLCC 所有品牌資訊匯總'!$C:$N,8,0) -> X5R | G23: =VLOOKUP(A23,'MLCC 所有品牌資訊匯總'!$C:$N,9,0) -> -55 to 85℃ | H23: =VLOOKUP(A23,'MLCC 所有品牌資訊匯總'!$C:$N,10,0) -> 476 | I23: =VLOOKUP(A23,'MLCC 所有品牌資訊匯總'!$C:$N,11,0) -> ±10 % | J23: =VLOOKUP(A23,'MLCC 所有品牌資訊匯總'!$C:$N,12,0) -> 16V

Sheet 尺寸
B1: Size L x Wmm (Inch)
B2: 0.6 x 0.3(0201)
A3: 15 | B3: 1.0 x 0.5(0402)
A4: 18 | B4: 1.6 x 0.8 (0603)
A5: 21 | B5: 2.0 x 1.25 (0805)
A6: 31 | B6: 3.2 x 1.6 (1206) | D6: TMK212BBJ106KG-T
A7: 32 | B7: 3.2 x 2.5 (1210)
B8: 4.5 x 3.2(1812)

Sheet 工作表1

Sheet 材質
A1: Temperature Characteristic | B1: Temp.Characteristic | C1: 静电容量变化或 温度系数
A2: X6T | B2: -55 to 105℃ | C2: +22%–33%
A3: X5R | B3: -55 to 85℃ | C3: ±15%
A4: X6S | B4: -55 to 105℃ | C4: ±22%
A5: X7T | B5: -55 to 125℃ | C5: +22%–33%
A6: COG | B6: -55 to 125℃ | C6: 0±30ppm/°C
A7: X7S | B7: -55 to 125℃ | C7: ±22%
A8: X7R | B8: -55 to 125℃ | C8: ±15%
A9: X7U | B9: -55 to 125℃ | C9: +22%–56%
A10: UJ2 | B10: -55 to 125℃ | C10: -750±120ppm/°C
